Workbook

Sheet Summary
A1: ValueEducator - Emerging Titans & Tiny Titans
A2: Watchlist + Portfolio tracker - Source: valueeducator.com - Returns as reported 2 Jun 2026
A3: Live CMP source: | B3: Power Query 'LivePrices' table (Data > Refresh All). CMP falls back to the 2-Jun snapshot until the query is set up (see PowerQuery_Live_Prices.md).
A6: Sheet | B6: What it is
A7: Watchlist (Combined) | B7: All 41 names + living thesis tracker (status, conviction, last-reviewed, what-breaks-it)
A8: Portfolio | B8: Enter Qty + Avg Cost for names you hold -> live value, weight, P&L, sector exposure
A9: Emerging Titans / Tiny Titans | B9: The two source portfolios, faithful snapshot + live CMP
A11: Tips
A12: Stale review | B12: 'Last Reviewed' older than 90 days turns red in the Combined sheet
A13: Concentration | B13: Portfolio weights over the limits (cells N1/N2) turn red
A15: DISCLAIMER: Reproduced from a third-party research service (ValueEducator) for personal tracking. NOT investment advice and not a buy/sell recommendation by the author. Verify every figure against primary sources before acting.

Sheet Emerging Titans
A1: No. | B1: Stock Name | C1: Sector | D1: Date of Rec | E1: Price at Rec (Rs) | F1: Allocation | G1: Action | H1: CMP (Rs) | I1: Return % (reported) | J1: Live P/L % | K1: Notes
A2: 1 | B2: Techno Electric & Engineering Ltd | C2: Power | D2: 46169 | E2: 1125 | F2: 0.05 | G2: Sell | H2: =IFERROR(xlookup(B2,liveprices!$a:$a,liveprices!$d:$d),1125) | I2: -0.134 | J2: =IF(E2=0,"",(H2-E2)/E2) | K2: Marked Sell 27 May 2026 (exit); source CMP shown = entry price
A3: 2 | B3: Oswal Pumps Ltd | C3: Capital Goods | D3: 46169 | E3: 362 | F3: 0.03 | G3: Sell | H3: =IFERROR(xlookup(B3,liveprices!$a:$a,liveprices!$d:$d),362) | I3: -0.368 | J3: =IF(E3=0,"",(H3-E3)/E3) | K3: Marked Sell 27 May 2026 (exit); source CMP shown = entry price
A4: 3 | B4: PNGS Reva Diamond Jewellery Limited | C4: Jewellery | D4: 46119 | E4: 379 | F4: 0.03 | G4: Buy | H4: =IFERROR(xlookup(B4,liveprices!$a:$a,liveprices!$d:$d),388) | I4: 0.023 | J4: =IF(E4=0,"",(H4-E4)/E4)
A5: 4 | B5: HBL Engineering | C5: Railway | D5: 46083 | E5: 666 | F5: 0.05 | G5: Buy | H5: =IFERROR(xlookup(B5,liveprices!$a:$a,liveprices!$d:$d),822) | I5: 0.235 | J5: =IF(E5=0,"",(H5-E5)/E5)
A6: 5 | B6: Centum Electronics Ltd | C6: Defence & Electronics | D6: 46083 | E6: 2685 | F6: 0.04 | G6: Buy | H6: =IFERROR(xlookup(B6,liveprices!$a:$a,liveprices!$d:$d),2880) | I6: 0.072 | J6: =IF(E6=0,"",(H6-E6)/E6)
A7: 6 | B7: SJS | C7: Auto | D7: 46034 | E7: 1635 | F7: 0.03 | G7: Buy | H7: =IFERROR(xlookup(B7,liveprices!$a:$a,liveprices!$d:$d),1698) | I7: 0.038 | J7: =IF(E7=0,"",(H7-E7)/E7)
A8: 7 | B8: Narayana Hrudayalaya Ltd | C8: Hospitals | D8: 46034 | E8: 1862 | F8: 0.03 | G8: Buy | H8: =IFERROR(xlookup(B8,liveprices!$a:$a,liveprices!$d:$d),1799) | I8: -0.033 | J8: =IF(E8=0,"",(H8-E8)/E8)
A9: 8 | B9: Force Motors | C9: Auto | D9: 46034 | E9: 19000 | F9: 0.03 | G9: Buy | H9: =IFERROR(xlookup(B9,liveprices!$a:$a,liveprices!$d:$d),20913) | I9: 0.1 | J9: =IF(E9=0,"",(H9-E9)/E9)
A10: 9 | B10: Samhi Hotels | C10: Hotels | D10: 46034 | E10: 189.5 | F10: 0.02 | G10: Buy | H10: =IFERROR(xlookup(B10,liveprices!$a:$a,liveprices!$d:$d),163.2) | I10: -0.138 | J10: =IF(E10=0,"",(H10-E10)/E10)
A11: 10 | B11: Gravita India Limited | C11: Recycling | D11: 46030 | E11: 1736 | F11: 0.03 | G11: Buy | H11: =IFERROR(xlookup(B11,liveprices!$a:$a,liveprices!$d:$d),1589) | I11: -0.084 | J11: =IF(E11=0,"",(H11-E11)/E11)
A12: 11 | B12: Timex Group | C12: Watches | D12: 46030 | E12: 335 | F12: 0.03 | G12: Buy | H12: =IFERROR(xlookup(B12,liveprices!$a:$a,liveprices!$d:$d),336) | I12: 0 | J12: =IF(E12=0,"",(H12-E12)/E12)
A13: 12 | B13: Federal bank financial services | C13: NBFC | D13: 46030 | E13: 159 | F13: 0.03 | G13: Buy | H13: =IFERROR(xlookup(B13,liveprices!$a:$a,liveprices!$d:$d),151) | I13: -0.04 | J13: =IF(E13=0,"",(H13-E13)/E13)
A14: 13 | B14: Praveg Ltd | C14: Hospitality | D14: 46021 | E14: 315 | F14: 0.03 | G14: Buy | H14: =IFERROR(xlookup(B14,liveprices!$a:$a,liveprices!$d:$d),260) | I14: -0.17 | J14: =IF(E14=0,"",(H14-E14)/E14)
A15: 14 | B15: Navkar Corporation Ltd | C15: Logistics Services | D15: 45986 | E15: 96.4 | F15: 0.03 | G15: Buy | H15: =IFERROR(xlookup(B15,liveprices!$a:$a,liveprices!$d:$d),106) | I15: 0.1 | J15: =IF(E15=0,"",(H15-E15)/E15)
A16: 15 | B16: Indo Tech Transformers Ltd | C16: Power | D16: 45923 | E16: 1759 | F16: 0.03 | G16: Buy | H16: =IFERROR(xlookup(B16,liveprices!$a:$a,liveprices!$d:$d),2406) | I16: 0.37 | J16: =IF(E16=0,"",(H16-E16)/E16)
A17: 16 | B17: Arkade Developers Ltd | C17: Infrastructure & Real Estate | D17: 45911 | E17: 179 | F17: 0.03 | G17: Buy | H17: =IFERROR(xlookup(B17,liveprices!$a:$a,liveprices!$d:$d),115) | I17: -0.35 | J17: =IF(E17=0,"",(H17-E17)/E17)
A18: 17 | B18: Sambhv Steel Tubes Ltd | C18: Ferrous & Non Ferrous Metals | D18: 45911 | E18: 114.5 | F18: 0.05 | G18: Buy | H18: =IFERROR(xlookup(B18,liveprices!$a:$a,liveprices!$d:$d),120) | I18: 0.048 | J18: =IF(E18=0,"",(H18-E18)/E18)
A19: 18 | B19: India Shelter Finance | C19: Finance | D19: 45821 | E19: 889 | F19: 0.05 | G19: Buy | H19: =IFERROR(xlookup(B19,liveprices!$a:$a,liveprices!$d:$d),805) | I19: -0.09 | J19: =IF(E19=0,"",(H19-E19)/E19)
A20: 19 | B20: Kilburn Engineering | C20: Engineering | D20: 45800 | E20: 454 | F20: 0.05 | G20: Buy | H20: =IFERROR(xlookup(B20,liveprices!$a:$a,liveprices!$d:$d),525) | I20: 0.156 | J20: =IF(E20=0,"",(H20-E20)/E20)
A21: 20 | B21: PSP Projects | C21: Infrastructure & Real Estate | D21: 45776 | E21: 637 | F21: 0.03 | G21: Buy | H21: =IFERROR(xlookup(B21,liveprices!$a:$a,liveprices!$d:$d),735) | I21: 0.16 | J21: =IF(E21=0,"",(H21-E21)/E21)
A22: 21 | B22: Frontier Spring | C22: Railway | D22: 45770 | E22: 761 | F22: 0.03 | G22: Buy | H22: =IFERROR(xlookup(B22,liveprices!$a:$a,liveprices!$d:$d),1492) | I22: 0.96 | J22: =IF(E22=0,"",(H22-E22)/E22)
A23: 22 | B23: CCL Products (India) Ltd | C23: FMCG | D23: 45736 | E23: 554 | F23: 0.03 | G23: Buy | H23: =IFERROR(xlookup(B23,liveprices!$a:$a,liveprices!$d:$d),1112) | I23: 1 | J23: =IF(E23=0,"",(H23-E23)/E23)
A24: 23 | B24: Tara Chand Infra Solution | C24: Infrastructure & Real Estate | D24: 45736 | E24: 58.3 | F24: 0.05 | G24: Buy | H24: =IFERROR(xlookup(B24,liveprices!$a:$a,liveprices!$d:$d),65.8) | I24: 0.128 | J24: =IF(E24=0,"",(H24-E24)/E24)
A25: 24 | B25: Mac Power CNC Machines Ltd | C25: Engineering | D25: 45727 | E25: 689 | F25: 0.03 | G25: Buy | H25: =IFERROR(xlookup(B25,liveprices!$a:$a,liveprices!$d:$d),1148) | I25: 0.667 | J25: =IF(E25=0,"",(H25-E25)/E25)
A26: 25 | B26: Paushak Ltd | C26: Chemical | D26: 45727 | E26: 521 | F26: 0.03 | G26: Buy | H26: =IFERROR(xlookup(B26,liveprices!$a:$a,liveprices!$d:$d),481) | I26: -0.076 | J26: =IF(E26=0,"",(H26-E26)/E26)
A27: 26 | B27: P N Gadgil Jewellers Ltd | C27: Diamond, Gems and Jewelry | D27: 45726 | E27: 543.6 | F27: 0.05 | G27: Buy | H27: =IFERROR(xlookup(B27,liveprices!$a:$a,liveprices!$d:$d),670) | I27: 0.232 | J27: =IF(E27=0,"",(H27-E27)/E27)
A28: 27 | B28: Shivalik Bi Metals Ltd | C28: Ferrous & Non Ferrous Metals | D28: 45726 | E28: 474 | F28: 0.03 | G28: Buy | H28: =IFERROR(xlookup(B28,liveprices!$a:$a,liveprices!$d:$d),530) | I28: 0.122 | J28: =IF(E28=0,"",(H28-E28)/E28)
A29: 28 | B29: S G Finserve Ltd | C29: Finance | D29: 45726 | E29: 343 | F29: 0.05 | G29: Buy | H29: =IFERROR(xlookup(B29,liveprices!$a:$a,liveprices!$d:$d),547) | I29: 0.59 | J29: =IF(E29=0,"",(H29-E29)/E29)
E30: Total allocation listed -> | F30: =SUM(F2:F29)

Sheet Tiny Titans
A1: No. | B1: Stock Name | C1: Sector | D1: Date of Rec | E1: Price at Rec (Rs) | F1: Rating | G1: Action | H1: CMP (Rs) | I1: Return % (reported) | J1: Live P/L % | K1: Notes
A2: 1 | B2: Maiden Forging | C2: Forging | D2: 46120 | E2: 74.5 | F2: 3 | G2: Buy | H2: =IFERROR(xlookup(B2,liveprices!$a:$a,liveprices!$d:$d),86) | I2: 0.154 | J2: =IF(E2=0,"",(H2-E2)/E2)
A3: 2 | B3: PNGS Gargi Fashion Jewellery Ltd | C3: Jewellery | D3: 46043 | E3: 968 | F3: 4 | G3: Buy | H3: =IFERROR(xlookup(B3,liveprices!$a:$a,liveprices!$d:$d),863) | I3: -0.108 | J3: =IF(E3=0,"",(H3-E3)/E3)
A4: 3 | B4: Patil Automation Ltd | C4: Automation | D4: 46038 | E4: 162 | F4: 3 | G4: Buy | H4: =IFERROR(xlookup(B4,liveprices!$a:$a,liveprices!$d:$d),156) | I4: -0.037 | J4: =IF(E4=0,"",(H4-E4)/E4)
A5: 4 | B5: Airfloa Rail Technology Ltd | C5: Railway | D5: 46034 | E5: 295 | F5: 4 | G5: Buy | H5: =IFERROR(xlookup(B5,liveprices!$a:$a,liveprices!$d:$d),329) | I5: 0.115 | J5: =IF(E5=0,"",(H5-E5)/E5)
A6: 5 | B6: Sat Kartar Shopping Ltd | C6: Health Care | D6: 46003 | E6: 160 | F6: 3 | G6: Buy | H6: =IFERROR(xlookup(B6,liveprices!$a:$a,liveprices!$d:$d),207) | I6: 0.293 | J6: =IF(E6=0,"",(H6-E6)/E6)
A7: 6 | B7: Z-Tech | C7: Waste management and recycling | D7: 45999 | E7: 515 | F7: 3 | G7: Buy | H7: =IFERROR(xlookup(B7,liveprices!$a:$a,liveprices!$d:$d),601) | I7: 0.167 | J7: =IF(E7=0,"",(H7-E7)/E7)
A8: 7 | B8: Sealmatic India Ltd | C8: Engineering | D8: 45950 | E8: 395.8 | F8: 3 | G8: Buy | H8: =IFERROR(xlookup(B8,liveprices!$a:$a,liveprices!$d:$d),430) | I8: 0.088 | J8: =IF(E8=0,"",(H8-E8)/E8)
A9: 8 | B9: CFF Fluid Control Ltd | C9: Defence | D9: 45944 | E9: 617 | F9: 3 | G9: Buy | H9: =IFERROR(xlookup(B9,liveprices!$a:$a,liveprices!$d:$d),770) | I9: 0.248 | J9: =IF(E9=0,"",(H9-E9)/E9)
A10: 9 | B10: Sathlokhar Synergys E&C | C10: Infrastructure & Real Estate | D10: 45943 | E10: 465 | F10: 3 | G10: Buy | H10: =IFERROR(xlookup(B10,liveprices!$a:$a,liveprices!$d:$d),409) | I10: -0.12 | J10: =IF(E10=0,"",(H10-E10)/E10)
A11: 10 | B11: Aluwind Infra-Tech Ltd | C11: Ferrous & Non Ferrous Metals | D11: 45943 | E11: 87 | F11: 3 | G11: Buy | H11: =IFERROR(xlookup(B11,liveprices!$a:$a,liveprices!$d:$d),57) | I11: -0.344 | J11: =IF(E11=0,"",(H11-E11)/E11)
A12: 11 | B12: Danish Power Ltd | C12: Power | D12: 45908 | E12: 897 | F12: 4 | G12: Buy | H12: =IFERROR(xlookup(B12,liveprices!$a:$a,liveprices!$d:$d),866) | I12: -0.034 | J12: =IF(E12=0,"",(H12-E12)/E12)
A13: 12 | B13: Wise Travel India Ltd | C13: Business Support | D13: 45895 | E13: 170 | F13: 3 | G13: Buy | H13: =IFERROR(xlookup(B13,liveprices!$a:$a,liveprices!$d:$d),106) | I13: -0.376 | J13: =IF(E13=0,"",(H13-E13)/E13)
A14: 13 | B14: Infollion Research Services Ltd | C14: Business Support | D14: 45895 | E14: 440 | F14: 4 | G14: Buy | H14: =IFERROR(xlookup(B14,liveprices!$a:$a,liveprices!$d:$d),245) | I14: -0.443 | J14: =IF(E14=0,"",(H14-E14)/E14)

Sheet Watchlist (Combined)
A1: Portfolio | B1: Stock Name | C1: Sector | D1: NSE Symbol | E1: BSE Code | F1: Date of Rec | G1: Price at Rec | H1: CMP | I1: Return % (reported) | J1: Live P/L % | K1: Alloc / Rating | L1: Action | M1: Thesis Status | N1: Conviction | O1: Last Reviewed | P1: What Breaks This | Q1: Notes
A2: Emerging Titans | B2: Techno Electric & Engineering Ltd | C2: Power | D2: TECHNOE | F2: 46169 | G2: 1125 | H2: =IFERROR(xlookup(B2,liveprices!$a:$a,liveprices!$d:$d),1125) | I2: -0.134 | J2: =IF(G2=0,"",(H2-G2)/G2) | K2: 5% | L2: Sell | O2: 46175 | Q2: Marked Sell 27 May 2026 (exit); source CMP shown = entry price
A3: Emerging Titans | B3: Oswal Pumps Ltd | C3: Capital Goods | D3: OSWALPUMPS | F3: 46169 | G3: 362 | H3: =IFERROR(xlookup(B3,liveprices!$a:$a,liveprices!$d:$d),362) | I3: -0.368 | J3: =IF(G3=0,"",(H3-G3)/G3) | K3: 3% | L3: Sell | O3: 46175 | Q3: Marked Sell 27 May 2026 (exit); source CMP shown = entry price
A4: Emerging Titans | B4: PNGS Reva Diamond Jewellery Limited | C4: Jewellery | D4: PNGSREVA | F4: 46119 | G4: 379 | H4: =IFERROR(xlookup(B4,liveprices!$a:$a,liveprices!$d:$d),388) | I4: 0.023 | J4: =IF(G4=0,"",(H4-G4)/G4) | K4: 3% | L4: Buy | O4: 46175
A5: Emerging Titans | B5: HBL Engineering | C5: Railway | D5: HBLENGINE | F5: 46083 | G5: 666 | H5: =IFERROR(xlookup(B5,liveprices!$a:$a,liveprices!$d:$d),822) | I5: 0.235 | J5: =IF(G5=0,"",(H5-G5)/G5) | K5: 5% | L5: Buy | O5: 46175
A6: Emerging Titans | B6: Centum Electronics Ltd | C6: Defence & Electronics | D6: CENTUM | F6: 46083 | G6: 2685 | H6: =IFERROR(xlookup(B6,liveprices!$a:$a,liveprices!$d:$d),2880) | I6: 0.072 | J6: =IF(G6=0,"",(H6-G6)/G6) | K6: 4% | L6: Buy | O6: 46175
A7: Emerging Titans | B7: SJS | C7: Auto | D7: SJS | F7: 46034 | G7: 1635 | H7: =IFERROR(xlookup(B7,liveprices!$a:$a,liveprices!$d:$d),1698) | I7: 0.038 | J7: =IF(G7=0,"",(H7-G7)/G7) | K7: 3% | L7: Buy | O7: 46175
A8: Emerging Titans | B8: Narayana Hrudayalaya Ltd | C8: Hospitals | D8: NH | F8: 46034 | G8: 1862 | H8: =IFERROR(xlookup(B8,liveprices!$a:$a,liveprices!$d:$d),1799) | I8: -0.033 | J8: =IF(G8=0,"",(H8-G8)/G8) | K8: 3% | L8: Buy | O8: 46175
A9: Emerging Titans | B9: Force Motors | C9: Auto | D9: FORCEMOT | F9: 46034 | G9: 19000 | H9: =IFERROR(xlookup(B9,liveprices!$a:$a,liveprices!$d:$d),20913) | I9: 0.1 | J9: =IF(G9=0,"",(H9-G9)/G9) | K9: 3% | L9: Buy | O9: 46175
A10: Emerging Titans | B10: Samhi Hotels | C10: Hotels | D10: SAMHI | F10: 46034 | G10: 189.5 | H10: =IFERROR(xlookup(B10,liveprices!$a:$a,liveprices!$d:$d),163.2) | I10: -0.138 | J10: =IF(G10=0,"",(H10-G10)/G10) | K10: 2% | L10: Buy | O10: 46175
A11: Emerging Titans | B11: Gravita India Limited | C11: Recycling | D11: GRAVITA | F11: 46030 | G11: 1736 | H11: =IFERROR(xlookup(B11,liveprices!$a:$a,liveprices!$d:$d),1589) | I11: -0.084 | J11: =IF(G11=0,"",(H11-G11)/G11) | K11: 3% | L11: Buy | O11: 46175
A12: Emerging Titans | B12: Timex Group | C12: Watches | D12: TIMEX | F12: 46030 | G12: 335 | H12: =IFERROR(xlookup(B12,liveprices!$a:$a,liveprices!$d:$d),336) | I12: 0 | J12: =IF(G12=0,"",(H12-G12)/G12) | K12: 3% | L12: Buy | O12: 46175
A13: Emerging Titans | B13: Federal bank financial services | C13: NBFC | D13: FEDFINA | F13: 46030 | G13: 159 | H13: =IFERROR(xlookup(B13,liveprices!$a:$a,liveprices!$d:$d),151) | I13: -0.04 | J13: =IF(G13=0,"",(H13-G13)/G13) | K13: 3% | L13: Buy | O13: 46175
A14: Emerging Titans | B14: Praveg Ltd | C14: Hospitality | D14: PRAVEG | F14: 46021 | G14: 315 | H14: =IFERROR(xlookup(B14,liveprices!$a:$a,liveprices!$d:$d),260) | I14: -0.17 | J14: =IF(G14=0,"",(H14-G14)/G14) | K14: 3% | L14: Buy | O14: 46175
A15: Emerging Titans | B15: Navkar Corporation Ltd | C15: Logistics Services | D15: NAVKARCORP | F15: 45986 | G15: 96.4 | H15: =IFERROR(xlookup(B15,liveprices!$a:$a,liveprices!$d:$d),106) | I15: 0.1 | J15: =IF(G15=0,"",(H15-G15)/G15) | K15: 3% | L15: Buy | O15: 46175
A16: Emerging Titans | B16: Indo Tech Transformers Ltd | C16: Power | D16: INDOTECH | F16: 45923 | G16: 1759 | H16: =IFERROR(xlookup(B16,liveprices!$a:$a,liveprices!$d:$d),2406) | I16: 0.37 | J16: =IF(G16=0,"",(H16-G16)/G16) | K16: 3% | L16: Buy | O16: 46175
A17: Emerging Titans | B17: Arkade Developers Ltd | C17: Infrastructure & Real Estate | D17: ARKADE | F17: 45911 | G17: 179 | H17: =IFERROR(xlookup(B17,liveprices!$a:$a,liveprices!$d:$d),115) | I17: -0.35 | J17: =IF(G17=0,"",(H17-G17)/G17) | K17: 3% | L17: Buy | O17: 46175
A18: Emerging Titans | B18: Sambhv Steel Tubes Ltd | C18: Ferrous & Non Ferrous Metals | D18: SAMBHV | F18: 45911 | G18: 114.5 | H18: =IFERROR(xlookup(B18,liveprices!$a:$a,liveprices!$d:$d),120) | I18: 0.048 | J18: =IF(G18=0,"",(H18-G18)/G18) | K18: 5% | L18: Buy | O18: 46175
A19: Emerging Titans | B19: India Shelter Finance | C19: Finance | D19: INDIASHLTR | F19: 45821 | G19: 889 | H19: =IFERROR(xlookup(B19,liveprices!$a:$a,liveprices!$d:$d),805) | I19: -0.09 | J19: =IF(G19=0,"",(H19-G19)/G19) | K19: 5% | L19: Buy | O19: 46175
A20: Emerging Titans | B20: Kilburn Engineering | C20: Engineering | E20: 522101 | F20: 45800 | G20: 454 | H20: =IFERROR(xlookup(B20,liveprices!$a:$a,liveprices!$d:$d),525) | I20: 0.156 | J20: =IF(G20=0,"",(H20-G20)/G20) | K20: 5% | L20: Buy | O20: 46175
A21: Emerging Titans | B21: PSP Projects | C21: Infrastructure & Real Estate | D21: PSPPROJECT | F21: 45776 | G21: 637 | H21: =IFERROR(xlookup(B21,liveprices!$a:$a,liveprices!$d:$d),735) | I21: 0.16 | J21: =IF(G21=0,"",(H21-G21)/G21) | K21: 3% | L21: Buy | O21: 46175
A22: Emerging Titans | B22: Frontier Spring | C22: Railway | D22: FRONTSP | F22: 45770 | G22: 761 | H22: =IFERROR(xlookup(B22,liveprices!$a:$a,liveprices!$d:$d),1492) | I22: 0.96 | J22: =IF(G22=0,"",(H22-G22)/G22) | K22: 3% | L22: Buy | O22: 46175
A23: Emerging Titans | B23: CCL Products (India) Ltd | C23: FMCG | D23: CCL | F23: 45736 | G23: 554 | H23: =IFERROR(xlookup(B23,liveprices!$a:$a,liveprices!$d:$d),1112) | I23: 1 | J23: =IF(G23=0,"",(H23-G23)/G23) | K23: 3% | L23: Buy | O23: 46175
A24: Emerging Titans | B24: Tara Chand Infra Solution | C24: Infrastructure & Real Estate | D24: TARACHAND | F24: 45736 | G24: 58.3 | H24: =IFERROR(xlookup(B24,liveprices!$a:$a,liveprices!$d:$d),65.8) | I24: 0.128 | J24: =IF(G24=0,"",(H24-G24)/G24) | K24: 5% | L24: Buy | O24: 46175
A25: Emerging Titans | B25: Mac Power CNC Machines Ltd | C25: Engineering | D25: MACPOWER | F25: 45727 | G25: 689 | H25: =IFERROR(xlookup(B25,liveprices!$a:$a,liveprices!$d:$d),1148) | I25: 0.667 | J25: =IF(G25=0,"",(H25-G25)/G25) | K25: 3% | L25: Buy | O25: 46175
A26: Emerging Titans | B26: Paushak Ltd | C26: Chemical | E26: 532742 | F26: 45727 | G26: 521 | H26: =IFERROR(xlookup(B26,liveprices!$a:$a,liveprices!$d:$d),481) | I26: -0.076 | J26: =IF(G26=0,"",(H26-G26)/G26) | K26: 3% | L26: Buy | O26: 46175
A27: Emerging Titans | B27: P N Gadgil Jewellers Ltd | C27: Diamond, Gems and Jewelry | D27: PNGJL | F27: 45726 | G27: 543.6 | H27: =IFERROR(xlookup(B27,liveprices!$a:$a,liveprices!$d:$d),670) | I27: 0.232 | J27: =IF(G27=0,"",(H27-G27)/G27) | K27: 5% | L27: Buy | O27: 46175
A28: Emerging Titans | B28: Shivalik Bi Metals Ltd | C28: Ferrous & Non Ferrous Metals | D28: SBCL | F28: 45726 | G28: 474 | H28: =IFERROR(xlookup(B28,liveprices!$a:$a,liveprices!$d:$d),530) | I28: 0.122 | J28: =IF(G28=0,"",(H28-G28)/G28) | K28: 3% | L28: Buy | O28: 46175
A29: Emerging Titans | B29: S G Finserve Ltd | C29: Finance | D29: SGFIN | F29: 45726 | G29: 343 | H29: =IFERROR(xlookup(B29,liveprices!$a:$a,liveprices!$d:$d),547) | I29: 0.59 | J29: =IF(G29=0,"",(H29-G29)/G29) | K29: 5% | L29: Buy | O29: 46175
A30: Tiny Titans | B30: Maiden Forging | C30: Forging | E30: 543874 | F30: 46120 | G30: 74.5 | H30: =IFERROR(xlookup(B30,liveprices!$a:$a,liveprices!$d:$d),86) | I30: 0.154 | J30: =IF(G30=0,"",(H30-G30)/G30) | K30: 3/5 | L30: Buy | O30: 46175
A31: Tiny Titans | B31: PNGS Gargi Fashion Jewellery Ltd | C31: Jewellery | E31: 543709 | F31: 46043 | G31: 968 | H31: =IFERROR(xlookup(B31,liveprices!$a:$a,liveprices!$d:$d),863) | I31: -0.108 | J31: =IF(G31=0,"",(H31-G31)/G31) | K31: 4/5 | L31: Buy | O31: 46175
A32: Tiny Titans | B32: Patil Automation Ltd | C32: Automation | F32: 46038 | G32: 162 | H32: =IFERROR(xlookup(B32,liveprices!$a:$a,liveprices!$d:$d),156) | I32: -0.037 | J32: =IF(G32=0,"",(H32-G32)/G32) | K32: 3/5 | L32: Buy | O32: 46175
A33: Tiny Titans | B33: Airfloa Rail Technology Ltd | C33: Railway | D33: AIRFLOA | F33: 46034 | G33: 295 | H33: =IFERROR(xlookup(B33,liveprices!$a:$a,liveprices!$d:$d),329) | I33: 0.115 | J33: =IF(G33=0,"",(H33-G33)/G33) | K33: 4/5 | L33: Buy | O33: 46175
A34: Tiny Titans | B34: Sat Kartar Shopping Ltd | C34: Health Care | D34: SATKARTAR | F34: 46003 | G34: 160 | H34: =IFERROR(xlookup(B34,liveprices!$a:$a,liveprices!$d:$d),207) | I34: 0.293 | J34: =IF(G34=0,"",(H34-G34)/G34) | K34: 3/5 | L34: Buy | O34: 46175
A35: Tiny Titans | B35: Z-Tech | C35: Waste management and recycling | D35: ZTECH | F35: 45999 | G35: 515 | H35: =IFERROR(xlookup(B35,liveprices!$a:$a,liveprices!$d:$d),601) | I35: 0.167 | J35: =IF(G35=0,"",(H35-G35)/G35) | K35: 3/5 | L35: Buy | O35: 46175
A36: Tiny Titans | B36: Sealmatic India Ltd | C36: Engineering | E36: 543782 | F36: 45950 | G36: 395.8 | H36: =IFERROR(xlookup(B36,liveprices!$a:$a,liveprices!$d:$d),430) | I36: 0.088 | J36: =IF(G36=0,"",(H36-G36)/G36) | K36: 3/5 | L36: Buy | O36: 46175
A37: Tiny Titans | B37: CFF Fluid Control Ltd | C37: Defence | E37: 543920 | F37: 45944 | G37: 617 | H37: =IFERROR(xlookup(B37,liveprices!$a:$a,liveprices!$d:$d),770) | I37: 0.248 | J37: =IF(G37=0,"",(H37-G37)/G37) | K37: 3/5 | L37: Buy | O37: 46175
A38: Tiny Titans | B38: Sathlokhar Synergys E&C | C38: Infrastructure & Real Estate | D38: SSEGL | F38: 45943 | G38: 465 | H38: =IFERROR(xlookup(B38,liveprices!$a:$a,liveprices!$d:$d),409) | I38: -0.12 | J38: =IF(G38=0,"",(H38-G38)/G38) | K38: 3/5 | L38: Buy | O38: 46175
A39: Tiny Titans | B39: Aluwind Infra-Tech Ltd | C39: Ferrous & Non Ferrous Metals | D39: ALUWIND | F39: 45943 | G39: 87 | H39: =IFERROR(xlookup(B39,liveprices!$a:$a,liveprices!$d:$d),57) | I39: -0.344 | J39: =IF(G39=0,"",(H39-G39)/G39) | K39: 3/5 | L39: Buy | O39: 46175
A40: Tiny Titans | B40: Danish Power Ltd | C40: Power | D40: DANISH | F40: 45908 | G40: 897 | H40: =IFERROR(xlookup(B40,liveprices!$a:$a,liveprices!$d:$d),866) | I40: -0.034 | J40: =IF(G40=0,"",(H40-G40)/G40) | K40: 4/5 | L40: Buy | O40: 46175
...

Sheet Portfolio
A1: Portfolio | B1: Stock Name | C1: Sector | D1: Qty | E1: Avg Cost | F1: CMP | G1: Invested | H1: Mkt Value | I1: P&L (Rs) | J1: P&L % | K1: Weight % | M1: Max single-name weight | N1: 0.1
A2: Emerging Titans | B2: Techno Electric & Engineering Ltd | C2: Power | D2: 100 | E2: 928.81 | F2: =IFERROR(XLOOKUP(B2,LivePrices!$A:$A,LivePrices!$D:$D),1065.8) | G2: =D2*E2 | H2: =D2*F2 | I2: =H2-G2 | J2: =IF(G2=0,"",(H2-G2)/G2) | K2: =IF($H$43=0,"",H2/$H$43) | M2: Max sector weight | N2: 0.25
A3: Emerging Titans | B3: Oswal Pumps Ltd | C3: Capital Goods | F3: =IFERROR(xlookup(B3,liveprices!$a:$a,liveprices!$d:$d),362) | G3: =D3*E3 | H3: =D3*F3 | I3: =H3-G3 | J3: =IF(G3=0,"",(H3-G3)/G3) | K3: =IF($H$43=0,"",H3/$H$43)
A4: Emerging Titans | B4: PNGS Reva Diamond Jewellery Limited | C4: Jewellery | D4: 250 | E4: 378.8 | F4: =IFERROR(XLOOKUP(B4,LivePrices!$A:$A,LivePrices!$D:$D),376.1) | G4: =D4*E4 | H4: =D4*F4 | I4: =H4-G4 | J4: =IF(G4=0,"",(H4-G4)/G4) | K4: =IF($H$43=0,"",H4/$H$43) | M4: Sector exposure
A5: Emerging Titans | B5: HBL Engineering | C5: Railway | F5: =IFERROR(xlookup(B5,liveprices!$a:$a,liveprices!$d:$d),822) | G5: =D5*E5 | H5: =D5*F5 | I5: =H5-G5 | J5: =IF(G5=0,"",(H5-G5)/G5) | K5: =IF($H$43=0,"",H5/$H$43) | M5: Sector | N5: Mkt Value | O5: % Port
A6: Emerging Titans | B6: Centum Electronics Ltd | C6: Defence & Electronics | D6: 40 | E6: 2749.85 | F6: =IFERROR(XLOOKUP(B6,LivePrices!$A:$A,LivePrices!$D:$D),3600.0) | G6: =D6*E6 | H6: =D6*F6 | I6: =H6-G6 | J6: =IF(G6=0,"",(H6-G6)/G6) | K6: =IF($H$43=0,"",H6/$H$43) | M6: Power | N6: =SUMIF($C$2:$C$42,M6,$H$2:$H$42) | O6: =IF($H$43=0,"",N6/$H$43)
A7: Emerging Titans | B7: SJS | C7: Auto | D7: 60 | E7: 1555.34 | F7: =IFERROR(XLOOKUP(B7,LivePrices!$A:$A,LivePrices!$D:$D),1993.0) | G7: =D7*E7 | H7: =D7*F7 | I7: =H7-G7 | J7: =IF(G7=0,"",(H7-G7)/G7) | K7: =IF($H$43=0,"",H7/$H$43) | M7: Capital Goods | N7: =SUMIF($C$2:$C$42,M7,$H$2:$H$42) | O7: =IF($H$43=0,"",N7/$H$43)
A8: Emerging Titans | B8: Narayana Hrudayalaya Ltd | C8: Hospitals | F8: =IFERROR(xlookup(B8,liveprices!$a:$a,liveprices!$d:$d),1799) | G8: =D8*E8 | H8: =D8*F8 | I8: =H8-G8 | J8: =IF(G8=0,"",(H8-G8)/G8) | K8: =IF($H$43=0,"",H8/$H$43) | M8: Jewellery | N8: =SUMIF($C$2:$C$42,M8,$H$2:$H$42) | O8: =IF($H$43=0,"",N8/$H$43)
A9: Emerging Titans | B9: Force Motors | C9: Auto | D9: 5 | E9: 20545.08 | F9: =IFERROR(XLOOKUP(B9,LivePrices!$A:$A,LivePrices!$D:$D),17833.0) | G9: =D9*E9 | H9: =D9*F9 | I9: =H9-G9 | J9: =IF(G9=0,"",(H9-G9)/G9) | K9: =IF($H$43=0,"",H9/$H$43) | M9: Railway | N9: =SUMIF($C$2:$C$42,M9,$H$2:$H$42) | O9: =IF($H$43=0,"",N9/$H$43)
A10: Emerging Titans | B10: Samhi Hotels | C10: Hotels | F10: =IFERROR(xlookup(B10,liveprices!$a:$a,liveprices!$d:$d),163.2) | G10: =D10*E10 | H10: =D10*F10 | I10: =H10-G10 | J10: =IF(G10=0,"",(H10-G10)/G10) | K10: =IF($H$43=0,"",H10/$H$43) | M10: Defence & Electronics | N10: =SUMIF($C$2:$C$42,M10,$H$2:$H$42) | O10: =IF($H$43=0,"",N10/$H$43)
A11: Emerging Titans | B11: Gravita India Limited | C11: Recycling | F11: =IFERROR(xlookup(B11,liveprices!$a:$a,liveprices!$d:$d),1589) | G11: =D11*E11 | H11: =D11*F11 | I11: =H11-G11 | J11: =IF(G11=0,"",(H11-G11)/G11) | K11: =IF($H$43=0,"",H11/$H$43) | M11: Auto | N11: =SUMIF($C$2:$C$42,M11,$H$2:$H$42) | O11: =IF($H$43=0,"",N11/$H$43)
A12: Emerging Titans | B12: Timex Group | C12: Watches | F12: =IFERROR(xlookup(B12,liveprices!$a:$a,liveprices!$d:$d),336) | G12: =D12*E12 | H12: =D12*F12 | I12: =H12-G12 | J12: =IF(G12=0,"",(H12-G12)/G12) | K12: =IF($H$43=0,"",H12/$H$43) | M12: Hospitals | N12: =SUMIF($C$2:$C$42,M12,$H$2:$H$42) | O12: =IF($H$43=0,"",N12/$H$43)
A13: Emerging Titans | B13: Federal bank financial services | C13: NBFC | F13: =IFERROR(xlookup(B13,liveprices!$a:$a,liveprices!$d:$d),151) | G13: =D13*E13 | H13: =D13*F13 | I13: =H13-G13 | J13: =IF(G13=0,"",(H13-G13)/G13) | K13: =IF($H$43=0,"",H13/$H$43) | M13: Hotels | N13: =SUMIF($C$2:$C$42,M13,$H$2:$H$42) | O13: =IF($H$43=0,"",N13/$H$43)
A14: Emerging Titans | B14: Praveg Ltd | C14: Hospitality | D14: 450 | E14: 216.56 | F14: =IFERROR(XLOOKUP(B14,LivePrices!$A:$A,LivePrices!$D:$D),240.0) | G14: =D14*E14 | H14: =D14*F14 | I14: =H14-G14 | J14: =IF(G14=0,"",(H14-G14)/G14) | K14: =IF($H$43=0,"",H14/$H$43) | M14: Recycling | N14: =SUMIF($C$2:$C$42,M14,$H$2:$H$42) | O14: =IF($H$43=0,"",N14/$H$43)
A15: Emerging Titans | B15: Navkar Corporation Ltd | C15: Logistics Services | F15: =IFERROR(xlookup(B15,liveprices!$a:$a,liveprices!$d:$d),106) | G15: =D15*E15 | H15: =D15*F15 | I15: =H15-G15 | J15: =IF(G15=0,"",(H15-G15)/G15) | K15: =IF($H$43=0,"",H15/$H$43) | M15: Watches | N15: =SUMIF($C$2:$C$42,M15,$H$2:$H$42) | O15: =IF($H$43=0,"",N15/$H$43)
A16: Emerging Titans | B16: Indo Tech Transformers Ltd | C16: Power | D16: 75 | E16: 1246.75 | F16: =IFERROR(XLOOKUP(B16,LivePrices!$A:$A,LivePrices!$D:$D),2722.8) | G16: =D16*E16 | H16: =D16*F16 | I16: =H16-G16 | J16: =IF(G16=0,"",(H16-G16)/G16) | K16: =IF($H$43=0,"",H16/$H$43) | M16: NBFC | N16: =SUMIF($C$2:$C$42,M16,$H$2:$H$42) | O16: =IF($H$43=0,"",N16/$H$43)
A17: Emerging Titans | B17: Arkade Developers Ltd | C17: Infrastructure & Real Estate | D17: 1000 | E17: 98.48 | F17: =IFERROR(XLOOKUP(B17,LivePrices!$A:$A,LivePrices!$D:$D),114.62) | G17: =D17*E17 | H17: =D17*F17 | I17: =H17-G17 | J17: =IF(G17=0,"",(H17-G17)/G17) | K17: =IF($H$43=0,"",H17/$H$43) | M17: Hospitality | N17: =SUMIF($C$2:$C$42,M17,$H$2:$H$42) | O17: =IF($H$43=0,"",N17/$H$43)
A18: Emerging Titans | B18: Sambhv Steel Tubes Ltd | C18: Ferrous & Non Ferrous Metals | D18: 1100 | E18: 98.58 | F18: =IFERROR(XLOOKUP(B18,LivePrices!$A:$A,LivePrices!$D:$D),104.57) | G18: =D18*E18 | H18: =D18*F18 | I18: =H18-G18 | J18: =IF(G18=0,"",(H18-G18)/G18) | K18: =IF($H$43=0,"",H18/$H$43) | M18: Logistics Services | N18: =SUMIF($C$2:$C$42,M18,$H$2:$H$42) | O18: =IF($H$43=0,"",N18/$H$43)
A19: Emerging Titans | B19: India Shelter Finance | C19: Finance | D19: 100 | E19: 746.12 | F19: =IFERROR(XLOOKUP(B19,LivePrices!$A:$A,LivePrices!$D:$D),771.55) | G19: =D19*E19 | H19: =D19*F19 | I19: =H19-G19 | J19: =IF(G19=0,"",(H19-G19)/G19) | K19: =IF($H$43=0,"",H19/$H$43) | M19: Infrastructure & Real Estate | N19: =SUMIF($C$2:$C$42,M19,$H$2:$H$42) | O19: =IF($H$43=0,"",N19/$H$43)
A20: Emerging Titans | B20: Kilburn Engineering | C20: Engineering | D20: 150 | E20: 400.74 | F20: =IFERROR(XLOOKUP(B20,LivePrices!$A:$A,LivePrices!$D:$D),495.95) | G20: =D20*E20 | H20: =D20*F20 | I20: =H20-G20 | J20: =IF(G20=0,"",(H20-G20)/G20) | K20: =IF($H$43=0,"",H20/$H$43) | M20: Ferrous & Non Ferrous Metals | N20: =SUMIF($C$2:$C$42,M20,$H$2:$H$42) | O20: =IF($H$43=0,"",N20/$H$43)
A21: Emerging Titans | B21: PSP Projects | C21: Infrastructure & Real Estate | D21: 100 | E21: 638.9 | F21: =IFERROR(XLOOKUP(B21,LivePrices!$A:$A,LivePrices!$D:$D),842.65) | G21: =D21*E21 | H21: =D21*F21 | I21: =H21-G21 | J21: =IF(G21=0,"",(H21-G21)/G21) | K21: =IF($H$43=0,"",H21/$H$43) | M21: Finance | N21: =SUMIF($C$2:$C$42,M21,$H$2:$H$42) | O21: =IF($H$43=0,"",N21/$H$43)
A22: Emerging Titans | B22: Frontier Spring | C22: Railway | D22: 75 | E22: 727.91 | F22: =IFERROR(XLOOKUP(B22,LivePrices!$A:$A,LivePrices!$D:$D),1560.0) | G22: =D22*E22 | H22: =D22*F22 | I22: =H22-G22 | J22: =IF(G22=0,"",(H22-G22)/G22) | K22: =IF($H$43=0,"",H22/$H$43) | M22: Engineering | N22: =SUMIF($C$2:$C$42,M22,$H$2:$H$42) | O22: =IF($H$43=0,"",N22/$H$43)
A23: Emerging Titans | B23: CCL Products (India) Ltd | C23: FMCG | D23: 110 | E23: 535.75 | F23: =IFERROR(XLOOKUP(B23,LivePrices!$A:$A,LivePrices!$D:$D),1073.0) | G23: =D23*E23 | H23: =D23*F23 | I23: =H23-G23 | J23: =IF(G23=0,"",(H23-G23)/G23) | K23: =IF($H$43=0,"",H23/$H$43) | M23: FMCG | N23: =SUMIF($C$2:$C$42,M23,$H$2:$H$42) | O23: =IF($H$43=0,"",N23/$H$43)
A24: Emerging Titans | B24: Tara Chand Infra Solution | C24: Infrastructure & Real Estate | D24: 1579 | E24: 60.15 | F24: =IFERROR(XLOOKUP(B24,LivePrices!$A:$A,LivePrices!$D:$D),60.24) | G24: =D24*E24 | H24: =D24*F24 | I24: =H24-G24 | J24: =IF(G24=0,"",(H24-G24)/G24) | K24: =IF($H$43=0,"",H24/$H$43) | M24: Chemical | N24: =SUMIF($C$2:$C$42,M24,$H$2:$H$42) | O24: =IF($H$43=0,"",N24/$H$43)
A25: Emerging Titans | B25: Mac Power CNC Machines Ltd | C25: Engineering | D25: 80 | E25: 695.65 | F25: =IFERROR(XLOOKUP(B25,LivePrices!$A:$A,LivePrices!$D:$D),931.25) | G25: =D25*E25 | H25: =D25*F25 | I25: =H25-G25 | J25: =IF(G25=0,"",(H25-G25)/G25) | K25: =IF($H$43=0,"",H25/$H$43) | M25: Diamond, Gems and Jewelry | N25: =SUMIF($C$2:$C$42,M25,$H$2:$H$42) | O25: =IF($H$43=0,"",N25/$H$43)
A26: Emerging Titans | B26: Paushak Ltd | C26: Chemical | F26: =IFERROR(xlookup(B26,liveprices!$a:$a,liveprices!$d:$d),481) | G26: =D26*E26 | H26: =D26*F26 | I26: =H26-G26 | J26: =IF(G26=0,"",(H26-G26)/G26) | K26: =IF($H$43=0,"",H26/$H$43) | M26: Forging | N26: =SUMIF($C$2:$C$42,M26,$H$2:$H$42) | O26: =IF($H$43=0,"",N26/$H$43)
A27: Emerging Titans | B27: P N Gadgil Jewellers Ltd | C27: Diamond, Gems and Jewelry | D27: 270 | E27: 541.8 | F27: =IFERROR(XLOOKUP(B27,LivePrices!$A:$A,LivePrices!$D:$D),548.3) | G27: =D27*E27 | H27: =D27*F27 | I27: =H27-G27 | J27: =IF(G27=0,"",(H27-G27)/G27) | K27: =IF($H$43=0,"",H27/$H$43) | M27: Automation | N27: =SUMIF($C$2:$C$42,M27,$H$2:$H$42) | O27: =IF($H$43=0,"",N27/$H$43)
A28: Emerging Titans | B28: Shivalik Bi Metals Ltd | C28: Ferrous & Non Ferrous Metals | F28: =IFERROR(xlookup(B28,liveprices!$a:$a,liveprices!$d:$d),530) | G28: =D28*E28 | H28: =D28*F28 | I28: =H28-G28 | J28: =IF(G28=0,"",(H28-G28)/G28) | K28: =IF($H$43=0,"",H28/$H$43) | M28: Health Care | N28: =SUMIF($C$2:$C$42,M28,$H$2:$H$42) | O28: =IF($H$43=0,"",N28/$H$43)
A29: Emerging Titans | B29: S G Finserve Ltd | C29: Finance | D29: 275 | E29: 334.38 | F29: =IFERROR(XLOOKUP(B29,LivePrices!$A:$A,LivePrices!$D:$D),571.0) | G29: =D29*E29 | H29: =D29*F29 | I29: =H29-G29 | J29: =IF(G29=0,"",(H29-G29)/G29) | K29: =IF($H$43=0,"",H29/$H$43) | M29: Waste management and recycling | N29: =SUMIF($C$2:$C$42,M29,$H$2:$H$42) | O29: =IF($H$43=0,"",N29/$H$43)
A30: Tiny Titans | B30: Maiden Forging | C30: Forging | F30: =IFERROR(xlookup(B30,liveprices!$a:$a,liveprices!$d:$d),86) | G30: =D30*E30 | H30: =D30*F30 | I30: =H30-G30 | J30: =IF(G30=0,"",(H30-G30)/G30) | K30: =IF($H$43=0,"",H30/$H$43) | M30: Defence | N30: =SUMIF($C$2:$C$42,M30,$H$2:$H$42) | O30: =IF($H$43=0,"",N30/$H$43)
A31: Tiny Titans | B31: PNGS Gargi Fashion Jewellery Ltd | C31: Jewellery | F31: =IFERROR(xlookup(B31,liveprices!$a:$a,liveprices!$d:$d),863) | G31: =D31*E31 | H31: =D31*F31 | I31: =H31-G31 | J31: =IF(G31=0,"",(H31-G31)/G31) | K31: =IF($H$43=0,"",H31/$H$43) | M31: Business Support | N31: =SUMIF($C$2:$C$42,M31,$H$2:$H$42) | O31: =IF($H$43=0,"",N31/$H$43)
A32: Tiny Titans | B32: Patil Automation Ltd | C32: Automation | D32: 600 | E32: 147.26 | F32: =IFERROR(XLOOKUP(B32,LivePrices!$A:$A,LivePrices!$D:$D),188.0) | G32: =D32*E32 | H32: =D32*F32 | I32: =H32-G32 | J32: =IF(G32=0,"",(H32-G32)/G32) | K32: =IF($H$43=0,"",H32/$H$43)
A33: Tiny Titans | B33: Airfloa Rail Technology Ltd | C33: Railway | D33: 1000 | E33: 259.98 | F33: =IFERROR(XLOOKUP(B33,LivePrices!$A:$A,LivePrices!$D:$D),320.05) | G33: =D33*E33 | H33: =D33*F33 | I33: =H33-G33 | J33: =IF(G33=0,"",(H33-G33)/G33) | K33: =IF($H$43=0,"",H33/$H$43)
A34: Tiny Titans | B34: Sat Kartar Shopping Ltd | C34: Health Care | D34: 800 | E34: 127.38 | F34: =IFERROR(XLOOKUP(B34,LivePrices!$A:$A,LivePrices!$D:$D),168.05) | G34: =D34*E34 | H34: =D34*F34 | I34: =H34-G34 | J34: =IF(G34=0,"",(H34-G34)/G34) | K34: =IF($H$43=0,"",H34/$H$43)
A35: Tiny Titans | B35: Z-Tech | C35: Waste management and recycling | D35: 300 | E35: 519.64 | F35: =IFERROR(XLOOKUP(B35,LivePrices!$A:$A,LivePrices!$D:$D),581.0) | G35: =D35*E35 | H35: =D35*F35 | I35: =H35-G35 | J35: =IF(G35=0,"",(H35-G35)/G35) | K35: =IF($H$43=0,"",H35/$H$43)
A36: Tiny Titans | B36: Sealmatic India Ltd | C36: Engineering | D36: 360 | E36: 336.46 | F36: =IFERROR(XLOOKUP(B36,LivePrices!$A:$A,LivePrices!$D:$D),376.95) | G36: =D36*E36 | H36: =D36*F36 | I36: =H36-G36 | J36: =IF(G36=0,"",(H36-G36)/G36) | K36: =IF($H$43=0,"",H36/$H$43)
A37: Tiny Titans | B37: CFF Fluid Control Ltd | C37: Defence | F37: =IFERROR(xlookup(B37,liveprices!$a:$a,liveprices!$d:$d),770) | G37: =D37*E37 | H37: =D37*F37 | I37: =H37-G37 | J37: =IF(G37=0,"",(H37-G37)/G37) | K37: =IF($H$43=0,"",H37/$H$43)
A38: Tiny Titans | B38: Sathlokhar Synergys E&C | C38: Infrastructure & Real Estate | D38: 400 | E38: 335.46 | F38: =IFERROR(XLOOKUP(B38,LivePrices!$A:$A,LivePrices!$D:$D),360.5) | G38: =D38*E38 | H38: =D38*F38 | I38: =H38-G38 | J38: =IF(G38=0,"",(H38-G38)/G38) | K38: =IF($H$43=0,"",H38/$H$43)
A39: Tiny Titans | B39: Aluwind Infra-Tech Ltd | C39: Ferrous & Non Ferrous Metals | F39: =IFERROR(xlookup(B39,liveprices!$a:$a,liveprices!$d:$d),57) | G39: =D39*E39 | H39: =D39*F39 | I39: =H39-G39 | J39: =IF(G39=0,"",(H39-G39)/G39) | K39: =IF($H$43=0,"",H39/$H$43)
A40: Tiny Titans | B40: Danish Power Ltd | C40: Power | D40: 300 | E40: 635.83 | F40: =IFERROR(XLOOKUP(B40,LivePrices!$A:$A,LivePrices!$D:$D),874.05) | G40: =D40*E40 | H40: =D40*F40 | I40: =H40-G40 | J40: =IF(G40=0,"",(H40-G40)/G40) | K40: =IF($H$43=0,"",H40/$H$43)
...
